Workbook
Name bbib10: 'Raw Data'!$N$23
Name bbib47: 'Raw Data'!$N$30
Name bbib48: 'Raw Data'!$N$35
Name bbib49: 'Raw Data'!$N$45
Name bbib54: 'Raw Data'!$R$61

Sheet Raw Data
C2: CO2 Uptake Conversions
C3: Number | D3: From 'Unit' to mmol/g | E3: Formula | F3: Notes | K3: All Units Coherent Unless Stated Otherwise
C4: 1 | D4: cm3(STP)/g | E4: "Value"/22.414
C5: 2 | D5: mg/g | E5: ("Value"/1000)/44.01
C6: 3 | D6: cm3(STP)/cm3 | E6: ("Value"/22.414)/Density | F6: Needs MOF Density | K6: Do I Need to Include Table headings for this Data???
K7: Is it worth mentioning conversions for things other than Uptake?
C8: 4 | D8: mL/g
B11: Review on Applications of Metal Organic Frameworks for CO2 Capture and the Performance Enhancement Mechanisms - Table 2 | J11: https://www.sciencedirect.com/science/article/pii/S1364032122003471?via%3Dihub
C12: Common Name | D12: CSD Code from Excel | E12: CSD Code from Lit. OR CCDC | F12: Trace Reference? | G12: Reported CO2 Uptake | H12: Reported Unit | I12: Standard Uptake, mmol/g | J12: Converted (Y/N) | K12: Formula Used (No.) | L12: Temperature, K | M12: Pressure, bar | N12: Surface Area, m2/g | O12: Pore Volume, cm3/g | P12: Pore Size Diameter, A | Q12: Density, g/cm3 | R12: Paper | S12: Table No. | T12: Notes/Questions | U12: Reference DOI
C13: Zeolite 13X | D13: =IFERROR(INDEX(Table_S12!$A$4:$A$324, MATCH(C13, Table_S12!$B$4:$B$324, 0)), "CSD Code Not Found") -> CSD Code Not Found | E13: / | G13: 7.4 | H13: mmol/g | I13: =G13 -> 7.4 | J13: N | L13: 298 | M13: 32 bar | N13: ND | O13: ND | P13: / | Q13: / | R13: [10] | S13: 2 | T13: BET Surface Areas | U13: A.R. Millward, O.M. Yaghi Metal-organic frameworks with exceptionally high capacity for storage of carbon dioxide at room temperature J Am Chem Soc, 127 (51) (2005), pp. 17998-17999
C14: MOF-2 | D14: =IFERROR(INDEX(Table_S12!$A$4:$A$324, MATCH(C14, Table_S12!$B$4:$B$324, 0)), "CSD Code Not Found") -> CSD Code Not Found | E14: ADUWON | G14: 3.2 | H14: mmol/g | I14: =G14 -> 3.2 | J14: N | L14: 298 | M14: 32 bar | N14: 345 | O14: / | P14: / | Q14: / | S14: 2 | U14: ^^^
C15: MOF-74 (Zn) | D15: =IFERROR(INDEX(Table_S12!$A$4:$A$324, MATCH(C15, Table_S12!$B$4:$B$324, 0)), "CSD Code Not Found") -> CSD Code Not Found | E15: ORIVOC | G15: 10.4 | H15: mmol/g | I15: =G15 -> 10.4 | J15: N | L15: 298 | M15: 32 bar | N15: 816 | O15: / | P15: / | Q15: / | S15: 2 | U15: ^^^
C16: MOF-505 | D16: =IFERROR(INDEX(Table_S12!$A$4:$A$324, MATCH(C16, Table_S12!$B$4:$B$324, 0)), "CSD Code Not Found") -> CSD Code Not Found | E16: LASYOU/RUVKAV | G16: 10.2 | H16: mmol/g | I16: =G16 -> 10.2 | J16: N | L16: 298 | M16: 32 bar | N16: 1547 | O16: / | P16: / | Q16: / | S16: 2 | U16: ^^^
C17: Cu3(BTC)2 (HKUST-1) | D17: =IFERROR(INDEX(Table_S12!$A$4:$A$324, MATCH(C17, Table_S12!$B$4:$B$324, 0)), "CSD Code Not Found") -> CSD Code Not Found | E17: DOTSOV 42 | G17: 10.7 | H17: mmol/g | I17: =G17 -> 10.7 | J17: N | L17: 298 | M17: 32 bar | N17: 1781 | O17: / | P17: / | Q17: / | S17: 2 | U17: ^^^
C18: MOF-177 | D18: =IFERROR(INDEX(Table_S12!$A$4:$A$324, MATCH(C18, Table_S12!$B$4:$B$324, 0)), "CSD Code Not Found") -> CSD Code Not Found | E18: BABRII | G18: 33.5 | H18: mmol/g | I18: =G18 -> 33.5 | J18: N | L18: 298 | M18: 32 bar | N18: 4508 | O18: / | P18: / | Q18: / | S18: 2 | U18: ^^^
H19: mmol/g
C20: MIL-100 (Fe) | D20: =IFERROR(INDEX(Table_S12!$A$4:$A$324, MATCH(C20, Table_S12!$B$4:$B$324, 0)), "CSD Code Not Found") -> CSD Code Not Found | E20: CIGXIA | G20: 18 | H20: mmol/g | I20: =G20 -> 18 | J20: N | L20: 304 | M20: 50 bar | N20: 1900 | O20: 1.1 | P20: / | Q20: / | R20: [47] | S20: 2 | U20: P.L. Llewellyn, S. Bourrelly, C. Serre, A. Vimont, M. Daturi, I. Hamon, L.S. Hwa Jhung High uptakes of CO2 and CH4 in mesoporous metal-organic frameworks MIL-100 and MIL-101 Langmuir, 24 (14) (2008), pp. 7245-7250
C21: MIL-101a | D21: =IFERROR(INDEX(Table_S12!$A$4:$A$324, MATCH(C21, Table_S12!$B$4:$B$324, 0)), "CSD Code Not Found") -> CSD Code Not Found | E21: OCUNAC | G21: 28 | H21: mmol/g | I21: =G21 -> 28 | J21: N | L21: 304 | M21: 50 bar | N21: 2800 | O21: 1.37 | P21: / | Q21: / | S21: 2 | U21: ^^^
C22: MIL-101b | D22: =IFERROR(INDEX(Table_S12!$A$4:$A$324, MATCH(C22, Table_S12!$B$4:$B$324, 0)), "CSD Code Not Found") -> CSD Code Not Found | E22: OCUNAC | G22: 34 | H22: mmol/g | I22: =G22 -> 34 | J22: N | L22: 304 | M22: 50 bar | N22: 3780 | O22: 1.74 | P22: / | Q22: / | S22: 2 | U22: ^^^
C23: MIL-101c | D23: =IFERROR(INDEX(Table_S12!$A$4:$A$324, MATCH(C23, Table_S12!$B$4:$B$324, 0)), "CSD Code Not Found") -> CSD Code Not Found | E23: OCUNAC | G23: 40 | H23: mmol/g | I23: =G23 -> 40 | J23: N | L23: 304 | M23: 50 bar | N23: 4230 | O23: 2.15 | P23: / | Q23: / | S23: 2 | U23: ^^^
H24: mmol/g
C25: MOF-177 | D25: =IFERROR(INDEX(Table_S12!$A$4:$A$324, MATCH(C25, Table_S12!$B$4:$B$324, 0)), "CSD Code Not Found") -> CSD Code Not Found | E25: BABRII | G25: 35.2 | H25: mmol/g | I25: =G25 -> 35.2 | J25: N | L25: 298 | M25: 50 bar | N25: 4500 | O25: 1.89 | P25: / | Q25: / | R25: [48] | S25: 2 | U25: H. Furukawa, N. Ko, Y.B. Go, N. Aratani, S.B. Choi, E. Choi, O.M. Yaghi Ultrahigh porosity in metal-organic frameworks Science, 329 (5990) (2010), pp. 424-428
C26: MOF-205 | D26: =IFERROR(INDEX(Table_S12!$A$4:$A$324, MATCH(C26, Table_S12!$B$4:$B$324, 0)), "CSD Code Not Found") -> CSD Code Not Found | E26: SUKXUS01 | G26: 38.1 | H26: mmol/g | I26: =G26 -> 38.1 | J26: N | L26: 298 | M26: 50 bar | N26: 4460 | O26: 2.16 | P26: / | Q26: / | S26: 2 | U26: ^^^
C27: MOF-200 | D27: =IFERROR(INDEX(Table_S12!$A$4:$A$324, MATCH(C27, Table_S12!$B$4:$B$324, 0)), "CSD Code Not Found") -> CSD Code Not Found | E27: CUSXOE | G27: 64.3 | H27: mmol/g | I27: =G27 -> 64.3 | J27: N | L27: 298 | M27: 50 bar | N27: 4530 | O27: 3.59 | P27: / | Q27: / | S27: 2 | U27: ^^^
C28: MOF-210 | D28: =IFERROR(INDEX(Table_S12!$A$4:$A$324, MATCH(C28, Table_S12!$B$4:$B$324, 0)), "CSD Code Not Found") -> CSD Code Not Found | E28: CUSYAR | G28: 65.2 | H28: mmol/g | I28: =G28 -> 65.2 | J28: N | L28: 298 | M28: 50 bar | N28: 6240 | O28: 3.6 | P28: / | Q28: / | S28: 2 | U28: ^^^
H29: mmol/g
C30: IRMOF-11 | D30: =IFERROR(INDEX(Table_S12!$A$4:$A$324, MATCH(C30, Table_S12!$B$4:$B$324, 0)), "CSD Code Not Found") -> CSD Code Not Found | E30: EDUVEE | G30: 14.7 | H30: mmol/g | I30: =G30 -> 14.7 | J30: N | L30: 298 | M30: 32 bar | N30: 2096 | O30: ND | P30: / | Q30: / | R30: [10] | S30: 2 | U30: A.R. Millward, O.M. Yaghi Metal-organic frameworks with exceptionally high capacity for storage of carbon dioxide at room temperature J Am Chem Soc, 127 (51) (2005), pp. 17998-17999
C31: IRMOF-3 | D31: =IFERROR(INDEX(Table_S12!$A$4:$A$324, MATCH(C31, Table_S12!$B$4:$B$324, 0)), "CSD Code Not Found") -> CSD Code Not Found | E31: EDUSUR | G31: 18.7 | H31: mmol/g | I31: =G31 -> 18.7 | J31: N | L31: 298 | M31: 32 bar | N31: 2160 | O31: / | P31: / | Q31: / | S31: 2 | U31: ^^^
C32: IRMOF-6 | D32: =IFERROR(INDEX(Table_S12!$A$4:$A$324, MATCH(C32, Table_S12!$B$4:$B$324, 0)), "CSD Code Not Found") -> CSD Code Not Found | E32: EDUTIG | G32: 19.5 | H32: mmol/g | I32: =G32 -> 19.5 | J32: N | L32: 298 | M32: 32 bar | N32: 2516 | O32: / | P32: / | Q32: / | S32: 2 | U32: ^^^
C33: IRMOF-1 | D33: =IFERROR(INDEX(Table_S12!$A$4:$A$324, MATCH(C33, Table_S12!$B$4:$B$324, 0)), "CSD Code Not Found") -> CSD Code Not Found | E33: EDUSIF | G33: 21.7 | H33: mmol/g | I33: =G33 -> 21.7 | J33: N | L33: 298 | M33: 32 bar | N33: 2833 | O33: / | P33: / | Q33: / | S33: 2 | U33: ^^^
C35: PCN-61 | D35: =IFERROR(INDEX(Table_S12!$A$4:$A$324, MATCH(C35, Table_S12!$B$4:$B$324, 0)), "CSD Code Not Found") -> VUJBIM | E35: VUJBIM | G35: 23.5 | H35: mmol/g | I35: =G35 -> 23.5 | J35: N | L35: 298 | M35: 35 bar | N35: 3000 | O35: 1.36 | P35: / | Q35: / | R35: [49] | S35: 2 | U35: D. Yuan, D. Zhao, D. Sun, H.C. Zhou An isoreticular series of metal–organic frameworks with dendritic hexacarboxylate ligands and exceptionally high gas-uptake capacity Angew Chem, 122 (31) (2010), pp. 5485-548
C36: PCN-66 | D36: =IFERROR(INDEX(Table_S12!$A$4:$A$324, MATCH(C36, Table_S12!$B$4:$B$324, 0)), "CSD Code Not Found") -> CSD Code Not Found | E36: VUJBOS | G36: 26.3 | H36: mmol/g | I36: =G36 -> 26.3 | J36: N | L36: 298 | M36: 35 bar | N36: 4000 | O36: 1.63 | P36: / | Q36: / | S36: 2 | U36: ^^^
C37: PCN-68 | D37: =IFERROR(INDEX(Table_S12!$A$4:$A$324, MATCH(C37, Table_S12!$B$4:$B$324, 0)), "CSD Code Not Found") -> HABRAF | E37: HABRAF | G37: 30.4 | H37: mmol/g | I37: =G37 -> 30.4 | J37: N | L37: 298 | M37: 35 bar | N37: 5109 | O37: 2.13 | P37: / | Q37: / | S37: 2 | U37: ^^^
B39: Review on Applications of Metal Organic Frameworks for CO2 Capture and the Performance Enhancement Mechanisms - Table 3
C40: HKUST-1 | D40: =IFERROR(INDEX(Table_S12!$A$4:$A$324, MATCH(C40, Table_S12!$B$4:$B$324, 0)), "CSD Code Not Found") -> DOTSOV42 | E40: DOTSOV42 | G40: 5.1 | H40: mmol/g | I40: =G40 -> 5.1 | J40: N | L40: 295 | M40: 1 | N40: 2134 | O40: / | P40: 5.05/10.45/12.4 | Q40: / | R40: [50] | S40: 3 | T40: Geometric Surface Area | U40: A.O. Yazaydin, R.Q. Snurr, T.H. Park, K. Koh, J. Liu, M.D. LeVan, A.I. Benin, P. Jakubczak, M. Lanuza, D.B. Galloway, J.J. Low Screening of metal-organic frameworks for carbon dioxide capture from flue gas using a combined experimental and modeling approach J Am Chem Soc, 131 (51) (2009), pp. 18198-18199
C41: UMCM-150 | D41: =IFERROR(INDEX(Table_S12!$A$4:$A$324, MATCH(C41, Table_S12!$B$4:$B$324, 0)), "CSD Code Not Found") -> CSD Code Not Found | E41: OKABEI | G41: 2.6 | H41: mmol/g | I41: =G41 -> 2.6 | J41: N | L41: 298 | M41: 1 | N41: 3236 | O41: / | P41: 9.25/10.55/13.25 | Q41: / | S41: 3 | U41: ^^^
C42: UMCM-150(N)2 | D42: =IFERROR(INDEX(Table_S12!$A$4:$A$324, MATCH(C42, Table_S12!$B$4:$B$324, 0)), "CSD Code Not Found") -> CSD Code Not Found | E42: OKABAE | G42: 2.7 | H42: mmol/g | I42: =G42 -> 2.7 | J42: N | L42: 298 | M42: 1 | N42: 3110 | O42: / | P42: 9.45/11.55/13.35 | Q42: / | S42: 3 | U42: ^^^
C43: MIL-47 | D43: =IFERROR(INDEX(Table_S12!$A$4:$A$324, MATCH(C43, Table_S12!$B$4:$B$324, 0)), "CSD Code Not Found") -> CSD Code Not Found | E43: HEJPIZ | G43: 2 | H43: mmol/g | I43: =G43 -> 2 | J43: N | L43: 298 | M43: 1 | N43: 1511 | O43: / | P43: 7.35 | Q43: / | S43: 3 | U43: ^^^
C44: MOF-177 | D44: =IFERROR(INDEX(Table_S12!$A$4:$A$324, MATCH(C44, Table_S12!$B$4:$B$324, 0)), "CSD Code Not Found") -> CSD Code Not Found | E44: BABRII | G44: 1.6 | H44: mmol/g | I44: =G44 -> 1.6 | J44: N | L44: 298 | M44: 1 | N44: 4833 | O44: / | P44: 10.45 | Q44: / | S44: 3 | U44: ^^^
C45: IRMOF-3 | D45: =IFERROR(INDEX(Table_S12!$A$4:$A$324, MATCH(C45, Table_S12!$B$4:$B$324, 0)), "CSD Code Not Found") -> CSD Code Not Found | E45: EDUSUR | G45: 1.1 | H45: mmol/g | I45: =G45 -> 1.1 | J45: N | L45: 298 | M45: 1 | N45: 3365 | O45: / | P45: 8.65/14.25 | Q45: / | S45: 3 | U45: ^^^
...

Sheet Clean Table (Backup)
C4: CSD Code | D4: Common Name | E4: CO2 Uptake, mmol/g | F4: Surface Area, m2/g | G4: Pore Volume, cm3/g | H4: Pore Size Diameter, A | I4: Density, g/cm3 | J4: Temperature, K | K4: Pressure, bar | L4: Notes | M4: References
C5: ='Raw Data'!E13 -> / | D5: ='Raw Data'!C13 -> Zeolite 13X | E5: ='Raw Data'!I13 -> 7.4 | F5: ='Raw Data'!N13 -> ND | G5: ='Raw Data'!O13 -> ND | H5: ='Raw Data'!P13 -> / | I5: ='Raw Data'!Q13 -> / | J5: ='Raw Data'!L13 -> 298 | K5: ='Raw Data'!M13 -> 32 bar | M5: ='Raw Data'!U13 -> A.R. Millward, O.M. Yaghi Metal-organic frameworks with exceptionally high capacity for storage of carbon dioxide at room temperature J Am Chem Soc, 127 (51) (2005), pp. 17998-17999
C6: ='Raw Data'!E14 -> ADUWON | D6: ='Raw Data'!C14 -> MOF-2 | E6: ='Raw Data'!I14 -> 3.2 | F6: ='Raw Data'!N14 -> 345 | G6: ='Raw Data'!O14 -> / | H6: ='Raw Data'!P14 -> / | I6: ='Raw Data'!Q14 -> / | J6: ='Raw Data'!L14 -> 298 | K6: ='Raw Data'!M14 -> 32 bar | M6: ='Raw Data'!U14 -> ^^^
C7: ='Raw Data'!E15 -> ORIVOC | D7: ='Raw Data'!C15 -> MOF-74 (Zn) | E7: ='Raw Data'!I15 -> 10.4 | F7: ='Raw Data'!N15 -> 816 | G7: ='Raw Data'!O15 -> / | H7: ='Raw Data'!P15 -> / | I7: ='Raw Data'!Q15 -> / | J7: ='Raw Data'!L15 -> 298 | K7: ='Raw Data'!M15 -> 32 bar | M7: ='Raw Data'!U15 -> ^^^
C8: ='Raw Data'!E16 -> LASYOU/RUVKAV | D8: ='Raw Data'!C16 -> MOF-505 | E8: ='Raw Data'!I16 -> 10.2 | F8: ='Raw Data'!N16 -> 1547 | G8: ='Raw Data'!O16 -> / | H8: ='Raw Data'!P16 -> / | I8: ='Raw Data'!Q16 -> / | J8: ='Raw Data'!L16 -> 298 | K8: ='Raw Data'!M16 -> 32 bar | M8: ='Raw Data'!U16 -> ^^^
C9: ='Raw Data'!E17 -> DOTSOV 42 | D9: ='Raw Data'!C17 -> Cu3(BTC)2 (HKUST-1) | E9: ='Raw Data'!I17 -> 10.7 | F9: ='Raw Data'!N17 -> 1781 | G9: ='Raw Data'!O17 -> / | H9: ='Raw Data'!P17 -> / | I9: ='Raw Data'!Q17 -> / | J9: ='Raw Data'!L17 -> 298 | K9: ='Raw Data'!M17 -> 32 bar | M9: ='Raw Data'!U17 -> ^^^
C10: ='Raw Data'!E18 -> BABRII | D10: ='Raw Data'!C18 -> MOF-177 | E10: ='Raw Data'!I18 -> 33.5 | F10: ='Raw Data'!N18 -> 4508 | G10: ='Raw Data'!O18 -> / | H10: ='Raw Data'!P18 -> / | I10: ='Raw Data'!Q18 -> / | J10: ='Raw Data'!L18 -> 298 | K10: ='Raw Data'!M18 -> 32 bar | M10: ='Raw Data'!U18 -> ^^^
C11: ='Raw Data'!E19 -> 0 | D11: ='Raw Data'!C19 -> 0 | E11: ='Raw Data'!I19 -> 0 | F11: ='Raw Data'!N19 -> 0 | G11: ='Raw Data'!O19 -> 0 | H11: ='Raw Data'!P19 -> 0 | I11: ='Raw Data'!Q19 -> 0 | J11: ='Raw Data'!L19 -> 0 | K11: ='Raw Data'!M19 -> 0 | M11: ='Raw Data'!U19 -> 0
C12: ='Raw Data'!E20 -> CIGXIA | D12: ='Raw Data'!C20 -> MIL-100 (Fe) | E12: ='Raw Data'!I20 -> 18 | F12: ='Raw Data'!N20 -> 1900 | G12: ='Raw Data'!O20 -> 1.1 | H12: ='Raw Data'!P20 -> / | I12: ='Raw Data'!Q20 -> / | J12: ='Raw Data'!L20 -> 304 | K12: ='Raw Data'!M20 -> 50 bar | M12: ='Raw Data'!U20 -> P.L. Llewellyn, S. Bourrelly, C. Serre, A. Vimont, M. Daturi, I. Hamon, L.S. Hwa Jhung High uptakes of CO2 and CH4 in mesoporous metal-organic frameworks MIL-100 and MIL-101 Langmuir, 24 (14) (2008), pp. 7245-7250
C13: ='Raw Data'!E21 -> OCUNAC | D13: ='Raw Data'!C21 -> MIL-101a | E13: ='Raw Data'!I21 -> 28 | F13: ='Raw Data'!N21 -> 2800 | G13: ='Raw Data'!O21 -> 1.37 | H13: ='Raw Data'!P21 -> / | I13: ='Raw Data'!Q21 -> / | J13: ='Raw Data'!L21 -> 304 | K13: ='Raw Data'!M21 -> 50 bar | M13: ='Raw Data'!U21 -> ^^^
C14: ='Raw Data'!E22 -> OCUNAC | D14: ='Raw Data'!C22 -> MIL-101b | E14: ='Raw Data'!I22 -> 34 | F14: ='Raw Data'!N22 -> 3780 | G14: ='Raw Data'!O22 -> 1.74 | H14: ='Raw Data'!P22 -> / | I14: ='Raw Data'!Q22 -> / | J14: ='Raw Data'!L22 -> 304 | K14: ='Raw Data'!M22 -> 50 bar | M14: ='Raw Data'!U22 -> ^^^
C15: ='Raw Data'!E23 -> OCUNAC | D15: ='Raw Data'!C23 -> MIL-101c | E15: ='Raw Data'!I23 -> 40 | F15: ='Raw Data'!N23 -> 4230 | G15: ='Raw Data'!O23 -> 2.15 | H15: ='Raw Data'!P23 -> / | I15: ='Raw Data'!Q23 -> / | J15: ='Raw Data'!L23 -> 304 | K15: ='Raw Data'!M23 -> 50 bar | M15: ='Raw Data'!U23 -> ^^^
C16: ='Raw Data'!E24 -> 0 | D16: ='Raw Data'!C24 -> 0 | E16: ='Raw Data'!I24 -> 0 | F16: ='Raw Data'!N24 -> 0 | G16: ='Raw Data'!O24 -> 0 | H16: ='Raw Data'!P24 -> 0 | I16: ='Raw Data'!Q24 -> 0 | J16: ='Raw Data'!L24 -> 0 | K16: ='Raw Data'!M24 -> 0 | M16: ='Raw Data'!U24 -> 0
... C68: ='Raw Data'!E76 -> / | D68: ='Raw Data'!C76 -> ZIF-82 | E68: ='Raw Data'!I76 -> look | F68: ='Raw Data'!N76 -> 1300 | G68: ='Raw Data'!O76 -> / | H68: ='Raw Data'!P76 -> 1.23nm | I68: ='Raw Data'!Q76 -> / | J68: ='Raw Data'!L76 -> 298 | K68: ='Raw Data'!M76 -> 1 | M68: ='Raw Data'!U76 -> ^^^
C69: ='Raw Data'!E77 -> 0 | D69: ='Raw Data'!C77 -> 0 | E69: ='Raw Data'!I77 -> 0 | F69: ='Raw Data'!Q77 -> 0 | G69: ='Raw Data'!R77 -> 0 | H69: ='Raw Data'!S77 -> 0 | I69: ='Raw Data'!T77 -> 0 | J69: ='Raw Data'!O77 -> 0 | K69: ='Raw Data'!P77 -> 0 | M69: ='Raw Data'!X77 -> 0
C70: ='Raw Data'!E78 -> 0 | D70: ='Raw Data'!C78 -> 0 | E70: ='Raw Data'!I78 -> 0 | F70: ='Raw Data'!Q78 -> 0 | G70: ='Raw Data'!R78 -> 0 | H70: ='Raw Data'!S78 -> 0 | I70: ='Raw Data'!T78 -> 0 | J70: ='Raw Data'!O78 -> 0 | K70: ='Raw Data'!P78 -> 0 | M70: ='Raw Data'!X78 -> 0
C71: ='Raw Data'!E79 -> CSD Code from Lit. | D71: ='Raw Data'!C79 -> Common Name | E71: ='Raw Data'!I79 -> CO2 Adsorption Capacity, mmol/g | F71: ='Raw Data'!Q79 -> Surface Area, m2/g | G71: ='Raw Data'!R79 -> Pore Volume, cm3/g | H71: ='Raw Data'!S79 -> Pore Size Diameter, A | I71: ='Raw Data'!T79 -> Density, g/cm3 | J71: ='Raw Data'!O79 -> Temperature, K | K71: ='Raw Data'!P79 -> Pressure, bar | M71: ='Raw Data'!X79 -> Reference DOI
C72: ='Raw Data'!E80 -> / | D72: ='Raw Data'!C80 -> Mg-MOF-74 | E72: ='Raw Data'!I80 -> 1.49 | F72: ='Raw Data'!Q80 -> / | G72: ='Raw Data'!R80 -> / | H72: ='Raw Data'!S80 -> / | I72: ='Raw Data'!T80 -> / | J72: ='Raw Data'!O80 -> 273,1 | K72: ='Raw Data'!P80 -> / | M72: ='Raw Data'!X80 -> Z.Y. Gao, L. Liang, X. Zhang, P. Xu, J.M. Sun Facile one-pot synthesis of zn/mg-MOF-74 with unsaturated coordination metal centers for efficient CO2 adsorption and conversion to cyclic carbonates ACS Appl. Mater. Interfaces, 13 (2021), pp. 61334-61345, 10.1021/acsami.1c20878
C73: ='Raw Data'!E81 -> ORIVOC | D73: ='Raw Data'!C81 -> Zn-MOF-74 | E73: ='Raw Data'!I81 -> 2.44 | F73: ='Raw Data'!Q81 -> / | G73: ='Raw Data'!R81 -> / | H73: ='Raw Data'!S81 -> / | I73: ='Raw Data'!T81 -> / | J73: ='Raw Data'!O81 -> 273,1 | K73: ='Raw Data'!P81 -> / | M73: ='Raw Data'!X81 -> ^^^
C74: ='Raw Data'!E82 -> ORIVOC | D74: ='Raw Data'!C82 -> Zn0.75Mg0.25-MOF-74 | E74: ='Raw Data'!I82 -> 3.99 | F74: ='Raw Data'!Q82 -> 667.6 | G74: ='Raw Data'!R82 -> / | H74: ='Raw Data'!S82 -> / | I74: ='Raw Data'!T82 -> / | J74: ='Raw Data'!O82 -> 273,1 | K74: ='Raw Data'!P82 -> / | M74: ='Raw Data'!X82 -> ^^^
C75: ='Raw Data'!E83 -> / | D75: ='Raw Data'!C83 -> Cu-OATA | E75: ='Raw Data'!I83 -> 2.24 | F75: ='Raw Data'!Q83 -> / | G75: ='Raw Data'!R83 -> / | H75: ='Raw Data'!S83 -> / | I75: ='Raw Data'!T83 -> / | J75: ='Raw Data'!O83 -> 298,1 | K75: ='Raw Data'!P83 -> / | M75: ='Raw Data'!X83 -> Y. Guclu, H. Erer, H. Demiral, C. Altintas, S. Keskin, N. Tumanov, B.L. Su, F. Semerci Oxalamide-functionalized metal organic frameworks for CO2 adsorption ACS Appl. Mater. Interfaces, 13 (2021), pp. 33188-33198
C76: ='Raw Data'!E84 -> / | D76: ='Raw Data'!C84 -> Cu(I)Zn@MIL-100(Fe)-10 | E76: ='Raw Data'!I84 -> 0.4 | F76: ='Raw Data'!Q84 -> / | G76: ='Raw Data'!R84 -> / | H76: ='Raw Data'!S84 -> / | I76: ='Raw Data'!T84 -> / | J76: ='Raw Data'!O84 -> 298,1 | K76: ='Raw Data'!P84 -> / | M76: ='Raw Data'!X84 -> V.N. Le, T.K. Vo, J.H. Lee, J.C. Kim, T.H. Kim, K.H. Oh, Y.S. Bae, S.K. Kwak, J. Kim A novel approach to prepare Cu(i)Zn@MIL-100(Fe) adsorbent with high co adsorption capacity, CO/CO2 selectivity and stability via controlled host-guest redox reaction Chem. Eng. J., 404 (2021), Article 126492
C77: ='Raw Data'!E85 -> BOHWUS | D77: ='Raw Data'!C85 -> MOF-808 | E77: ='Raw Data'!I85 -> 1.36 | F77: ='Raw Data'!Q85 -> / | G77: ='Raw Data'!R85 -> / | H77: ='Raw Data'!S85 -> / | I77: ='Raw Data'!T85 -> / | J77: ='Raw Data'!O85 -> 298,1 | K77: ='Raw Data'!P85 -> / | M77: ='Raw Data'!X85 -> J.M. Park, D.K. Yoo, S.H. Jhung Selective CO2 adsorption over functionalized Zr-based metal organic framework under atmospheric or lower pressure: Contribution of functional groups to adsorption Chem. Eng. J., 402 (2020), Article 126254
C78: ='Raw Data'!E86 -> BOHWUS | D78: ='Raw Data'!C86 -> MOF-808-EDTA | E78: ='Raw Data'!I86 -> 1.48 | F78: ='Raw Data'!Q86 -> / | G78: ='Raw Data'!R86 -> / | H78: ='Raw Data'!S86 -> / | I78: ='Raw Data'!T86 -> / | J78: ='Raw Data'!O86 -> 298,1 | K78: ='Raw Data'!P86 -> / | M78: ='Raw Data'!X86 -> ^^^
C79: ='Raw Data'!E87 -> BOHWUS | D79: ='Raw Data'!C87 -> MOF-808-EDTA-ED-1.2 | E79: ='Raw Data'!I87 -> 1.62 | F79: ='Raw Data'!Q87 -> / | G79: ='Raw Data'!R87 -> / | H79: ='Raw Data'!S87 -> / | I79: ='Raw Data'!T87 -> / | J79: ='Raw Data'!O87 -> 298,1 | K79: ='Raw Data'!P87 -> / | M79: ='Raw Data'!X87 -> ^^^
C80: ='Raw Data'!E88 -> / | D80: ='Raw Data'!C88 -> Mg2(dobpdc)(3-4-3) | E80: ='Raw Data'!I88 -> 2 | F80: ='Raw Data'!Q88 -> / | G80: ='Raw Data'!R88 -> / | H80: ='Raw Data'!S88 -> / | I80: ='Raw Data'!T88 -> / | J80: ='Raw Data'!O88 -> 273,0.04 | K80: ='Raw Data'!P88 -> / | M80: ='Raw Data'!X88 -> E.J. Kim, R.L. Siegelman, H.Z.H. Jiang, A.C. Forse, J.H. Lee, J.D. Martell, P.J. Milner, J.M. Falkowski, J.B. Neaton, J.A. Reimer, S.C. Weston, J.R. Long Cooperative carbon capture and steam regeneration with tetraamine-appended metal-organic frameworks Science, 369 (2020), p. 392-+
... C123: ='Raw Data'!E131 -> 0 | D123: ='Raw Data'!C131 -> 0 | E123: ='Raw Data'!I131 -> 0 | F123: ='Raw Data'!Q131 -> 0 | G123: ='Raw Data'!R131 -> 0 | H123: ='Raw Data'!S131 -> 0 | I123: ='Raw Data'!T131 -> 0 | J123: ='Raw Data'!O131 -> 0 | K123: ='Raw Data'!P131 -> 0 | M123: ='Raw Data'!X131 -> 0

Sheet Clean Table
A1: From Table_S1 | M1: From Articles | X1: Missing Properties References
A4: CSD Code | B4: Common Name | C4: Metal Type | D4: Density (g/cm3) | E4: Pore Limiting Diameter, | F4: Largest Cavity Diameter | G4: Volumetric Surface Area (m2/cm3) | H4: Geometric Surface Area (m2/g) | I4: Void Fraction | J4: Pore volume (cm3/g) | K4: NOTES | M4: Common Name | N4: CO2 Uptake, mmol/g | O4: Surface Area, m2/g | P4: Pore Volume, cm3/g | Q4: Pore Size Diameter, A | R4: Density, g/cm3 | S4: Temperature, K | T4: Pressure, bar | U4: Notes | V4: References | X4: Surface Area, m2/g | Y4: Pore Volume, cm3/g | Z4: Pore Diameter, A | AA4: Density, g/cm3
A5: ='Raw Data'!E13 -> / | B5: =M5 -> Zeolite 13X | C5: =VLOOKUP($A5, Table_S1!$B$10:$K$5118, 2, FALSE) -> #N/A | D5: =VLOOKUP($A5, Table_S1!$B$10:$K$5118, 3, FALSE) -> #N/A | E5: =VLOOKUP($A5, Table_S1!$B$10:$K$5118, 4, FALSE) -> #N/A | F5: =VLOOKUP($A5, Table_S1!$B$10:$K$5118, 5, FALSE) -> #N/A | G5: =VLOOKUP($A5, Table_S1!$B$10:$K$5118, 6, FALSE) -> #N/A | H5: =VLOOKUP($A5, Table_S1!$B$10:$K$5118, 7, FALSE) -> #N/A | I5: =VLOOKUP($A5, Table_S1!$B$10:$K$5118, 8, FALSE) -> #N/A | J5: =VLOOKUP($A5, Table_S1!$B$10:$K$5118, 9, FALSE) -> #N/A | K5: =VLOOKUP($A5, Table_S1!$B$10:$K$5118, 10, FALSE) -> #N/A | M5: ='Raw Data'!C13 -> Zeolite 13X | N5: ='Raw Data'!I13 -> 7.4 | O5: 625.3 | P5: 0.3 | Q5: 1.92nm = 19.2A | R5: ='Raw Data'!Q13 -> / | S5: ='Raw Data'!L13 -> 298 | T5: ='Raw Data'!M13 -> 32 bar | V5: ='Raw Data'!U13 -> A.R. Millward, O.M. Yaghi Metal-organic frameworks with exceptionally high capacity for storage of carbon dioxide at room temperature J Am Chem Soc, 127 (51) (2005), pp. 17998-17999 | X5: Amir Mohammad Najafi, Saeed Soltanali, Farhad Khorashe, Hamid Ghassabzadeh, Effect of binder on CO2, CH4, and N2 adsorption behavior, structural properties, and diffusion coefficients on extruded zeolite 13X, Chemosphere, Volume 324, 2023, 138275, SSN 0045-6535, | Y5: Amir Mohammad Najafi, Saeed Soltanali, Farhad Khorashe, Hamid Ghassabzadeh, Effect of binder on CO2, CH4, and N2 adsorption behavior, structural properties, and diffusion coefficients on extruded zeolite 13X, Chemosphere, Volume 324, 2023, 138275, SSN 0045-6535, | Z5: Amir Mohammad Najafi, Saeed Soltanali, Farhad Khorashe, Hamid Ghassabzadeh, Effect of binder on CO2, CH4, and N2 adsorption behavior, structural properties, and diffusion coefficients on extruded zeolite 13X, Chemosphere, Volume 324, 2023, 138275, SSN 0045-6535,
A6: ='Raw Data'!E14 -> ADUWON | B6: =M6 -> MOF-2 | C6: =VLOOKUP($A6, Table_S1!$B$10:$K$5118, 2, FALSE) -> #N/A | D6: =VLOOKUP($A6, Table_S1!$B$10:$K$5118, 3, FALSE) -> #N/A | E6: =VLOOKUP($A6, Table_S1!$B$10:$K$5118, 4, FALSE) -> #N/A | F6: =VLOOKUP($A6, Table_S1!$B$10:$K$5118, 5, FALSE) -> #N/A | G6: =VLOOKUP($A6, Table_S1!$B$10:$K$5118, 6, FALSE) -> #N/A | H6: =VLOOKUP($A6, Table_S1!$B$10:$K$5118, 7, FALSE) -> #N/A | I6: =VLOOKUP($A6, Table_S1!$B$10:$K$5118, 8, FALSE) -> #N/A | J6: =VLOOKUP($A6, Table_S1!$B$10:$K$5118, 9, FALSE) -> #N/A | K6: =VLOOKUP($A6, Table_S1!$B$10:$K$5118, 10, FALSE) -> #N/A | M6: ='Raw Data'!C14 -> MOF-2 | N6: ='Raw Data'!I14 -> 3.2 | O6: ='Raw Data'!N14 -> 345 | P6: 0.227 | Q6: 5A | R6: ='Raw Data'!Q14 -> / | S6: ='Raw Data'!L14 -> 298 | T6: ='Raw Data'!M14 -> 32 bar | V6: ='Raw Data'!U14 -> ^^^ | Y6: H. Li, M. Eddaoudi, T.L. Groy, O.M. Yaghi, J. Am. Chem. Soc. 120, 8571 (1998) | PD: A.R. Millward, O.M. Yaghi Metal-organic frameworks with exceptionally high capacity for storage of carbon dioxide at room temperature J Am Chem Soc, 127 (51) (2005), pp. 17998-17999 | Z6: A.R. Millward, O.M. Yaghi Metal-organic frameworks with exceptionally high capacity for storage of carbon dioxide at room temperature J Am Chem Soc, 127 (51) (2005), pp. 17998-17999
A7: ='Raw Data'!E15 -> ORIVOC | B7: =M7 -> MOF-74 (Zn) | C7: =VLOOKUP($A7, Table_S1!$B$10:$K$5118, 2, FALSE) -> #N/A | D7: =VLOOKUP($A7, Table_S1!$B$10:$K$5118, 3, FALSE) -> #N/A | E7: =VLOOKUP($A7, Table_S1!$B$10:$K$5118, 4, FALSE) -> #N/A | F7: =VLOOKUP($A7, Table_S1!$B$10:$K$5118, 5, FALSE) -> #N/A | G7: =VLOOKUP($A7, Table_S1!$B$10:$K$5118, 6, FALSE) -> #N/A | H7: =VLOOKUP($A7, Table_S1!$B$10:$K$5118, 7, FALSE) -> #N/A | I7: =VLOOKUP($A7, Table_S1!$B$10:$K$5118, 8, FALSE) -> #N/A | J7: =VLOOKUP($A7, Table_S1!$B$10:$K$5118, 9, FALSE) -> #N/A | K7: =VLOOKUP($A7, Table_S1!$B$10:$K$5118, 10, FALSE) -> #N/A | M7: ='Raw Data'!C15 -> MOF-74 (Zn) | N7: ='Raw Data'!I15 -> 10.4 | O7: ='Raw Data'!N15 -> 816 | P7: ='Raw Data'!O15 -> / | Q7: 11A | R7: ='Raw Data'!Q15 -> / | S7: ='Raw Data'!L15 -> 298 | T7: ='Raw Data'!M15 -> 32 bar | V7: ='Raw Data'!U15 -> ^^^ | Z7: A.R. Millward, O.M. Yaghi Metal-organic frameworks with exceptionally high capacity for storage of carbon dioxide at room temperature J Am Chem Soc, 127 (51) (2005), pp. 17998-17999
A8: ='Raw Data'!E16 -> LASYOU/RUVKAV | B8: =M8 -> MOF-505 | C8: =VLOOKUP($A8, Table_S1!$B$10:$K$5118, 2, FALSE) -> #N/A | D8: =VLOOKUP($A8, Table_S1!$B$10:$K$5118, 3, FALSE) -> #N/A | E8: =VLOOKUP($A8, Table_S1!$B$10:$K$5118, 4, FALSE) -> #N/A | F8: =VLOOKUP($A8, Table_S1!$B$10:$K$5118, 5, FALSE) -> #N/A | G8: =VLOOKUP($A8, Table_S1!$B$10:$K$5118, 6, FALSE) -> #N/A | H8: =VLOOKUP($A8, Table_S1!$B$10:$K$5118, 7, FALSE) -> #N/A | I8: =VLOOKUP($A8, Table_S1!$B$10:$K$5118, 8, FALSE) -> #N/A | J8: =VLOOKUP($A8, Table_S1!$B$10:$K$5118, 9, FALSE) -> #N/A | K8: =VLOOKUP($A8, Table_S1!$B$10:$K$5118, 10, FALSE) -> #N/A | M8: ='Raw Data'!C16 -> MOF-505 | N8: ='Raw Data'!I16 -> 10.2 | O8: ='Raw Data'!N16 -> 1547 | P8: ='Raw Data'!O16 -> / | Q8: 8, 10A | R8: ='Raw Data'!Q16 -> / | S8: ='Raw Data'!L16 -> 298 | T8: ='Raw Data'!M16 -> 32 bar | V8: ='Raw Data'!U16 -> ^^^ | Z8: A.R. Millward, O.M. Yaghi Metal-organic frameworks with exceptionally high capacity for storage of carbon dioxide at room temperature J Am Chem Soc, 127 (51) (2005), pp. 17998-17999
A9: ='Raw Data'!E17 -> DOTSOV 42 | B9: =M9 -> Cu3(BTC)2 (HKUST-1) | C9: =VLOOKUP($A9, Table_S1!$B$10:$K$5118, 2, FALSE) -> #N/A | D9: =VLOOKUP($A9, Table_S1!$B$10:$K$5118, 3, FALSE) -> #N/A | E9: =VLOOKUP($A9, Table_S1!$B$10:$K$5118, 4, FALSE) -> #N/A | F9: =VLOOKUP($A9, Table_S1!$B$10:$K$5118, 5, FALSE) -> #N/A | G9: =VLOOKUP($A9, Table_S1!$B$10:$K$5118, 6, FALSE) -> #N/A | H9: =VLOOKUP($A9, Table_S1!$B$10:$K$5118, 7, FALSE) -> #N/A | I9: =VLOOKUP($A9, Table_S1!$B$10:$K$5118, 8, FALSE) -> #N/A | J9: =VLOOKUP($A9, Table_S1!$B$10:$K$5118, 9, FALSE) -> #N/A | K9: =VLOOKUP($A9, Table_S1!$B$10:$K$5118, 10, FALSE) -> #N/A | M9: ='Raw Data'!C17 -> Cu3(BTC)2 (HKUST-1) | N9: ='Raw Data'!I17 -> 10.7 | O9: ='Raw Data'!N17 -> 1781 | P9: 0.801 | Q9: 5, 15A | R9: ='Raw Data'!Q17 -> / | S9: ='Raw Data'!L17 -> 298 | T9: ='Raw Data'!M17 -> 32 bar | V9: ='Raw Data'!U17 -> ^^^ | Y9: Furukawa H., Miller M. A., Yaghi O. M., Independent verification of the saturation hydrogen uptake in MOF-177 and establishment of a benchmark for hydrogen adsorption in metal–organic frameworks. J. Mater. Chem. 17, 3197 (2007). | Z9: A.R. Millward, O.M. Yaghi Metal-organic frameworks with exceptionally high capacity for storage of carbon dioxide at room temperature J Am Chem Soc, 127 (51) (2005), pp. 17998-17999
A10: ='Raw Data'!E18 -> BABRII | B10: =M10 -> MOF-177 | C10: =VLOOKUP($A10, Table_S1!$B$10:$K$5118, 2, FALSE) -> #N/A | D10: =VLOOKUP($A10, Table_S1!$B$10:$K$5118, 3, FALSE) -> #N/A | E10: =VLOOKUP($A10, Table_S1!$B$10:$K$5118, 4, FALSE) -> #N/A | F10: =VLOOKUP($A10, Table_S1!$B$10:$K$5118, 5, FALSE) -> #N/A | G10: =VLOOKUP($A10, Table_S1!$B$10:$K$5118, 6, FALSE) -> #N/A | H10: =VLOOKUP($A10, Table_S1!$B$10:$K$5118, 7, FALSE) -> #N/A | I10: =VLOOKUP($A10, Table_S1!$B$10:$K$5118, 8, FALSE) -> #N/A | J10: =VLOOKUP($A10, Table_S1!$B$10:$K$5118, 9, FALSE) -> #N/A | K10: =VLOOKUP($A10, Table_S1!$B$10:$K$5118, 10, FALSE) -> #N/A | M10: ='Raw Data'!C18 -> MOF-177 | N10: ='Raw Data'!I18 -> 33.5 | O10: ='Raw Data'!N18 -> 4508 | P10: 1.89 | Q10: 11, 17A | R10: 0.43 | S10: ='Raw Data'!L18 -> 298 | T10: ='Raw Data'!M18 -> 32 bar | V10: ='Raw Data'!U18 -> ^^^ | Y10: Furukawa H., Miller M. A., Yaghi O. M., Independent verification of the saturation hydrogen uptake in MOF-177 and establishment of a benchmark for hydrogen adsorption in metal–organic frameworks. J. Mater. Chem. 17, 3197 (2007). | Z10: A.R. Millward, O.M. Yaghi Metal-organic frameworks with exceptionally high capacity for storage of carbon dioxide at room temperature J Am Chem Soc, 127 (51) (2005), pp. 17998-17999 | AA10: Furukawa H., Miller M. A., Yaghi O. M., Independent verification of the saturation hydrogen uptake in MOF-177 and establishment of a benchmark for hydrogen adsorption in metal–organic frameworks. J. Mater. Chem. 17, 3197 (2007).
A11: ='Raw Data'!E20 -> CIGXIA | B11: =M11 -> MIL-100 (Fe) | C11: =VLOOKUP($A11, Table_S1!$B$10:$K$5118, 2, FALSE) -> Fe | D11: =VLOOKUP($A11, Table_S1!$B$10:$K$5118, 3, FALSE) -> 0.684425 | E11: =VLOOKUP($A11, Table_S1!$B$10:$K$5118, 4, FALSE) -> 11.8329 | F11: =VLOOKUP($A11, Table_S1!$B$10:$K$5118, 5, FALSE) -> 28.49654 | G11: =VLOOKUP($A11, Table_S1!$B$10:$K$5118, 6, FALSE) -> 1304.16 | H11: =VLOOKUP($A11, Table_S1!$B$10:$K$5118, 7, FALSE) -> 1905.48 | I11: =VLOOKUP($A11, Table_S1!$B$10:$K$5118, 8, FALSE) -> 0.774255 | J11: =VLOOKUP($A11, Table_S1!$B$10:$K$5118, 9, FALSE) -> 1.11547 | K11: =VLOOKUP($A11, Table_S1!$B$10:$K$5118, 10, FALSE) -> removed free oxygen atoms + bound oxygen atoms + hydrogenation + geom. Minimization (fine/cg) | M11: ='Raw Data'!C20 -> MIL-100 (Fe) | N11: ='Raw Data'!I20 -> 18 | O11: ='Raw Data'!N20 -> 1900 | P11: ='Raw Data'!O20 -> 1.1 | Q11: ='Raw Data'!P20 -> / | R11: 0.7 | S11: ='Raw Data'!L20 -> 304 | T11: ='Raw Data'!M20 -> 50 bar | V11: ='Raw Data'!U20 -> P.L. Llewellyn, S. Bourrelly, C. Serre, A. Vimont, M. Daturi, I. Hamon, L.S. Hwa Jhung High uptakes of CO2 and CH4 in mesoporous metal-organic frameworks MIL-100 and MIL-101 Langmuir, 24 (14) (2008), pp. 7245-7250 | AA11: P.L. Llewellyn, S. Bourrelly, C. Serre, A. Vimont, M. Daturi, I. Hamon, L.S. Hwa Jhung High uptakes of CO2 and CH4 in mesoporous metal-organic frameworks MIL-100 and MIL-101 Langmuir, 24 (14) (2008), pp. 7245-7250
A12: ='Raw Data'!E21 -> OCUNAC | B12: =M12 -> MIL-101a | C12: =VLOOKUP($A12, Table_S1!$B$10:$K$5118, 2, FALSE) -> Cr | D12: =VLOOKUP($A12, Table_S1!$B$10:$K$5118, 3, FALSE) -> 0.427517 | E12: =VLOOKUP($A12, Table_S1!$B$10:$K$5118, 4, FALSE) -> 14.04664 | F12: =VLOOKUP($A12, Table_S1!$B$10:$K$5118, 5, FALSE) -> 36.1506 | G12: =VLOOKUP($A12, Table_S1!$B$10:$K$5118, 6, FALSE) -> 1345.1 | H12: =VLOOKUP($A12, Table_S1!$B$10:$K$5118, 7, FALSE) -> 3146.31 | I12: =VLOOKUP($A12, Table_S1!$B$10:$K$5118, 8, FALSE) -> 0.844869 | J12: =VLOOKUP($A12, Table_S1!$B$10:$K$5118, 9, FALSE) -> 1.96082 | K12: =VLOOKUP($A12, Table_S1!$B$10:$K$5118, 10, FALSE) -> hydrogenation + geom. Minimization (fine setting/cg) | M12: ='Raw Data'!C21 -> MIL-101a | N12: ='Raw Data'!I21 -> 28 | O12: ='Raw Data'!N21 -> 2800 | P12: ='Raw Data'!O21 -> 1.37 | Q12: ='Raw Data'!P21 -> / | R12: 0.4 | S12: ='Raw Data'!L21 -> 304 | T12: ='Raw Data'!M21 -> 50 bar | V12: ='Raw Data'!U21 -> ^^^ | AA12: P.L. Llewellyn, S. Bourrelly, C. Serre, A. Vimont, M. Daturi, I. Hamon, L.S. Hwa Jhung High uptakes of CO2 and CH4 in mesoporous metal-organic frameworks MIL-100 and MIL-101 Langmuir, 24 (14) (2008), pp. 7245-7250
A13: ='Raw Data'!E22 -> OCUNAC | B13: =M13 -> MIL-101b | C13: =VLOOKUP($A13, Table_S1!$B$10:$K$5118, 2, FALSE) -> Cr | D13: =VLOOKUP($A13, Table_S1!$B$10:$K$5118, 3, FALSE) -> 0.427517 | E13: =VLOOKUP($A13, Table_S1!$B$10:$K$5118, 4, FALSE) -> 14.04664 | F13: =VLOOKUP($A13, Table_S1!$B$10:$K$5118, 5, FALSE) -> 36.1506 | G13: =VLOOKUP($A13, Table_S1!$B$10:$K$5118, 6, FALSE) -> 1345.1 | H13: =VLOOKUP($A13, Table_S1!$B$10:$K$5118, 7, FALSE) -> 3146.31 | I13: =VLOOKUP($A13, Table_S1!$B$10:$K$5118, 8, FALSE) -> 0.844869 | J13: =VLOOKUP($A13, Table_S1!$B$10:$K$5118, 9, FALSE) -> 1.96082 | K13: =VLOOKUP($A13, Table_S1!$B$10:$K$5118, 10, FALSE) -> hydrogenation + geom. Minimization (fine setting/cg) | M13: ='Raw Data'!C22 -> MIL-101b | N13: ='Raw Data'!I22 -> 34 | O13: ='Raw Data'!N22 -> 3780 | P13: ='Raw Data'!O22 -> 1.74 | Q13: ='Raw Data'!P22 -> / | R13: 0.4 | S13: ='Raw Data'!L22 -> 304 | T13: ='Raw Data'!M22 -> 50 bar | V13: ='Raw Data'!U22 -> ^^^ | AA13: P.L. Llewellyn, S. Bourrelly, C. Serre, A. Vimont, M. Daturi, I. Hamon, L.S. Hwa Jhung High uptakes of CO2 and CH4 in mesoporous metal-organic frameworks MIL-100 and MIL-101 Langmuir, 24 (14) (2008), pp. 7245-7250
A14: ='Raw Data'!E23 -> OCUNAC | B14: =M14 -> MIL-101c | C14: =VLOOKUP($A14, Table_S1!$B$10:$K$5118, 2, FALSE) -> Cr | D14: =VLOOKUP($A14, Table_S1!$B$10:$K$5118, 3, FALSE) -> 0.427517 | E14: =VLOOKUP($A14, Table_S1!$B$10:$K$5118, 4, FALSE) -> 14.04664 | F14: =VLOOKUP($A14, Table_S1!$B$10:$K$5118, 5, FALSE) -> 36.1506 | G14: =VLOOKUP($A14, Table_S1!$B$10:$K$5118, 6, FALSE) -> 1345.1 | H14: =VLOOKUP($A14, Table_S1!$B$10:$K$5118, 7, FALSE) -> 3146.31 | I14: =VLOOKUP($A14, Table_S1!$B$10:$K$5118, 8, FALSE) -> 0.844869 | J14: =VLOOKUP($A14, Table_S1!$B$10:$K$5118, 9, FALSE) -> 1.96082 | K14: =VLOOKUP($A14, Table_S1!$B$10:$K$5118, 10, FALSE) -> hydrogenation + geom. Minimization (fine setting/cg) | M14: ='Raw Data'!C23 -> MIL-101c | N14: ='Raw Data'!I23 -> 40 | O14: ='Raw Data'!N23 -> 4230 | P14: ='Raw Data'!O23 -> 2.15 | Q14: ='Raw Data'!P23 -> / | R14: 0.4 | S14: ='Raw Data'!L23 -> 304 | T14: ='Raw Data'!M23 -> 50 bar | V14: ='Raw Data'!U23 -> ^^^ | AA14: P.L. Llewellyn, S. Bourrelly, C. Serre, A. Vimont, M. Daturi, I. Hamon, L.S. Hwa Jhung High uptakes of CO2 and CH4 in mesoporous metal-organic frameworks MIL-100 and MIL-101 Langmuir, 24 (14) (2008), pp. 7245-7251
A15: ='Raw Data'!E25 -> BABRII | B15: =M15 -> MOF-177 | C15: =VLOOKUP($A15, Table_S1!$B$10:$K$5118, 2, FALSE) -> #N/A | D15: =VLOOKUP($A15, Table_S1!$B$10:$K$5118, 3, FALSE) -> #N/A | E15: =VLOOKUP($A15, Table_S1!$B$10:$K$5118, 4, FALSE) -> #N/A | F15: =VLOOKUP($A15, Table_S1!$B$10:$K$5118, 5, FALSE) -> #N/A | G15: =VLOOKUP($A15, Table_S1!$B$10:$K$5118, 6, FALSE) -> #N/A | H15: =VLOOKUP($A15, Table_S1!$B$10:$K$5118, 7, FALSE) -> #N/A | I15: =VLOOKUP($A15, Table_S1!$B$10:$K$5118, 8, FALSE) -> #N/A | J15: =VLOOKUP($A15, Table_S1!$B$10:$K$5118, 9, FALSE) -> #N/A | K15: =VLOOKUP($A15, Table_S1!$B$10:$K$5118, 10, FALSE) -> #N/A | M15: ='Raw Data'!C25 -> MOF-177 | N15: ='Raw Data'!I25 -> 35.2 | O15: ='Raw Data'!N25 -> 4500 | P15: ='Raw Data'!O25 -> 1.89 | Q15: 11, 17 A | R15: 0.43 | S15: ='Raw Data'!L25 -> 298 | T15: ='Raw Data'!M25 -> 50 bar | V15: ='Raw Data'!U25 -> H. Furukawa, N. Ko, Y.B. Go, N. Aratani, S.B. Choi, E. Choi, O.M. Yaghi Ultrahigh porosity in metal-organic frameworks Science, 329 (5990) (2010), pp. 424-428 | Z15: A.R. Millward, O.M. Yaghi Metal-organic frameworks with exceptionally high capacity for storage of carbon dioxide at room temperature J Am Chem Soc, 127 (51) (2005), pp. 17998-17999 | AA15: P.L. Llewellyn, S. Bourrelly, C. Serre, A. Vimont, M. Daturi, I. Hamon, L.S. Hwa Jhung High uptakes of CO2 and CH4 in mesoporous metal-organic frameworks MIL-100 and MIL-101 Langmuir, 24 (14) (2008), pp. 7245-7252
A16: ='Raw Data'!E26 -> SUKXUS01 | B16: =M16 -> MOF-205 | C16: =VLOOKUP($A16, Table_S1!$B$10:$K$5118, 2, FALSE) -> #N/A | D16: =VLOOKUP($A16, Table_S1!$B$10:$K$5118, 3, FALSE) -> #N/A | E16: =VLOOKUP($A16, Table_S1!$B$10:$K$5118, 4, FALSE) -> #N/A | F16: =VLOOKUP($A16, Table_S1!$B$10:$K$5118, 5, FALSE) -> #N/A | G16: =VLOOKUP($A16, Table_S1!$B$10:$K$5118, 6, FALSE) -> #N/A | H16: =VLOOKUP($A16, Table_S1!$B$10:$K$5118, 7, FALSE) -> #N/A | I16: =VLOOKUP($A16, Table_S1!$B$10:$K$5118, 8, FALSE) -> #N/A | J16: =VLOOKUP($A16, Table_S1!$B$10:$K$5118, 9, FALSE) -> #N/A | K16: =VLOOKUP($A16, Table_S1!$B$10:$K$5118, 10, FALSE) -> #N/A | M16: ='Raw Data'!C26 -> MOF-205 | N16: ='Raw Data'!I26 -> 38.1 | O16: ='Raw Data'!N26 -> 4460 | P16: ='Raw Data'!O26 -> 2.16 | Q16: ='Raw Data'!P26 -> / | R16: 0.38 | S16: ='Raw Data'!L26 -> 298 | T16: ='Raw Data'!M26 -> 50 bar | V16: ='Raw Data'!U26 -> ^^^ | AA16: D: H. Furukawa, N. Ko, Y.B. Go, N. Aratani, S.B. Choi, E. Choi, O.M. Yaghi Ultrahigh porosity in metal-organic frameworks Science, 329 (5990) (2010), pp. 424-428
A17: ='Raw Data'!E27 -> CUSXOE | B17: =M17 -> MOF-200 | C17: =VLOOKUP($A17, Table_S1!$B$10:$K$5118, 2, FALSE) -> #N/A | D17: =VLOOKUP($A17, Table_S1!$B$10:$K$5118, 3, FALSE) -> #N/A | E17: =VLOOKUP($A17, Table_S1!$B$10:$K$5118, 4, FALSE) -> #N/A | F17: =VLOOKUP($A17, Table_S1!$B$10:$K$5118, 5, FALSE) -> #N/A | G17: =VLOOKUP($A17, Table_S1!$B$10:$K$5118, 6, FALSE) -> #N/A | H17: =VLOOKUP($A17, Table_S1!$B$10:$K$5118, 7, FALSE) -> #N/A | I17: =VLOOKUP($A17, Table_S1!$B$10:$K$5118, 8, FALSE) -> #N/A | J17: =VLOOKUP($A17, Table_S1!$B$10:$K$5118, 9, FALSE) -> #N/A | K17: =VLOOKUP($A17, Table_S1!$B$10:$K$5118, 10, FALSE) -> #N/A | M17: ='Raw Data'!C27 -> MOF-200 | N17: ='Raw Data'!I27 -> 64.3 | O17: ='Raw Data'!N27 -> 4530 | P17: ='Raw Data'!O27 -> 3.59 | Q17: ='Raw Data'!P27 -> / | R17: 0.22 | S17: ='Raw Data'!L27 -> 298 | T17: ='Raw Data'!M27 -> 50 bar | V17: ='Raw Data'!U27 -> ^^^ | AA17: D: H. Furukawa, N. Ko, Y.B. Go, N. Aratani, S.B. Choi, E. Choi, O.M. Yaghi Ultrahigh porosity in metal-organic frameworks Science, 329 (5990) (2010), pp. 424-428
A18: ='Raw Data'!E28 -> CUSYAR | B18: =M18 -> MOF-210 | C18: =VLOOKUP($A18, Table_S1!$B$10:$K$5118, 2, FALSE) -> #N/A | D18: =VLOOKUP($A18, Table_S1!$B$10:$K$5118, 3, FALSE) -> #N/A | E18: =VLOOKUP($A18, Table_S1!$B$10:$K$5118, 4, FALSE) -> #N/A | F18: =VLOOKUP($A18, Table_S1!$B$10:$K$5118, 5, FALSE) -> #N/A | G18: =VLOOKUP($A18, Table_S1!$B$10:$K$5118, 6, FALSE) -> #N/A | H18: =VLOOKUP($A18, Table_S1!$B$10:$K$5118, 7, FALSE) -> #N/A | I18: =VLOOKUP($A18, Table_S1!$B$10:$K$5118, 8, FALSE) -> #N/A | J18: =VLOOKUP($A18, Table_S1!$B$10:$K$5118, 9, FALSE) -> #N/A | K18: =VLOOKUP($A18, Table_S1!$B$10:$K$5118, 10, FALSE) -> #N/A | M18: ='Raw Data'!C28 -> MOF-210 | N18: ='Raw Data'!I28 -> 65.2 | O18: ='Raw Data'!N28 -> 6240 | P18: ='Raw Data'!O28 -> 3.6 | Q18: ='Raw Data'!P28 -> / | R18: 0.25 | S18: ='Raw Data'!L28 -> 298 | T18: ='Raw Data'!M28 -> 50 bar | V18: ='Raw Data'!U28 -> ^^^ | AA18: D: H. Furukawa, N. Ko, Y.B. Go, N. Aratani, S.B. Choi, E. Choi, O.M. Yaghi Ultrahigh porosity in metal-organic frameworks Science, 329 (5990) (2010), pp. 424-428
A19: ='Raw Data'!E30 -> EDUVEE | B19: =M19 -> IRMOF-11 | C19: =VLOOKUP($A19, Table_S1!$B$10:$K$5118, 2, FALSE) -> #N/A | D19: =VLOOKUP($A19, Table_S1!$B$10:$K$5118, 3, FALSE) -> #N/A | E19: =VLOOKUP($A19, Table_S1!$B$10:$K$5118, 4, FALSE) -> #N/A | F19: =VLOOKUP($A19, Table_S1!$B$10:$K$5118, 5, FALSE) -> #N/A | G19: =VLOOKUP($A19, Table_S1!$B$10:$K$5118, 6, FALSE) -> #N/A | H19: =VLOOKUP($A19, Table_S1!$B$10:$K$5118, 7, FALSE) -> #N/A | I19: =VLOOKUP($A19, Table_S1!$B$10:$K$5118, 8, FALSE) -> #N/A | J19: =VLOOKUP($A19, Table_S1!$B$10:$K$5118, 9, FALSE) -> #N/A | K19: =VLOOKUP($A19, Table_S1!$B$10:$K$5118, 10, FALSE) -> #N/A | M19: ='Raw Data'!C30 -> IRMOF-11 | N19: ='Raw Data'!I30 -> 14.7 | O19: ='Raw Data'!N30 -> 2096 | P19: ='Raw Data'!O30 -> ND | Q19: ='Raw Data'!P30 -> / | R19: ='Raw Data'!Q30 -> / | S19: ='Raw Data'!L30 -> 298 | T19: ='Raw Data'!M30 -> 32 bar | V19: ='Raw Data'!U30 -> A.R. Millward, O.M. Yaghi Metal-organic frameworks with exceptionally high capacity for storage of carbon dioxide at room temperature J Am Chem Soc, 127 (51) (2005), pp. 17998-17999
A20: ='Raw Data'!E31 -> EDUSUR | B20: =M20 -> IRMOF-3 | C20: =VLOOKUP($A20, Table_S1!$B$10:$K$5118, 2, FALSE) -> #N/A | D20: =VLOOKUP($A20, Table_S1!$B$10:$K$5118, 3, FALSE) -> #N/A | E20: =VLOOKUP($A20, Table_S1!$B$10:$K$5118, 4, FALSE) -> #N/A | F20: =VLOOKUP($A20, Table_S1!$B$10:$K$5118, 5, FALSE) -> #N/A | G20: =VLOOKUP($A20, Table_S1!$B$10:$K$5118, 6, FALSE) -> #N/A | H20: =VLOOKUP($A20, Table_S1!$B$10:$K$5118, 7, FALSE) -> #N/A | I20: =VLOOKUP($A20, Table_S1!$B$10:$K$5118, 8, FALSE) -> #N/A | J20: =VLOOKUP($A20, Table_S1!$B$10:$K$5118, 9, FALSE) -> #N/A | K20: =VLOOKUP($A20, Table_S1!$B$10:$K$5118, 10, FALSE) -> #N/A | M20: ='Raw Data'!C31 -> IRMOF-3 | N20: ='Raw Data'!I31 -> 18.7 | O20: ='Raw Data'!N31 -> 2160 | P20: 1.204 | Q20: 10, 15A | R20: ='Raw Data'!Q31 -> / | S20: ='Raw Data'!L31 -> 298 | T20: ='Raw Data'!M31 -> 32 bar | V20: ='Raw Data'!U31 -> ^^^ | Y20: Furukawa H., Miller M. A., Yaghi O. M., Independent verification of the saturation hydrogen uptake in MOF-177 and establishment of a benchmark for hydrogen adsorption in metal–organic frameworks. J. Mater. Chem. 17, 3197 (2007). | Z20: PD: A.R. Millward, O.M. Yaghi Metal-organic frameworks with exceptionally high capacity for storage of carbon dioxide at room temperature J Am Chem Soc, 127 (51) (2005), pp. 17998-17999
A21: ='Raw Data'!E32 -> EDUTIG | B21: =M21 -> IRMOF-6 | C21: =VLOOKUP($A21, Table_S1!$B$10:$K$5118, 2, FALSE) -> #N/A | D21: =VLOOKUP($A21, Table_S1!$B$10:$K$5118, 3, FALSE) -> #N/A | E21: =VLOOKUP($A21, Table_S1!$B$10:$K$5118, 4, FALSE) -> #N/A | F21: =VLOOKUP($A21, Table_S1!$B$10:$K$5118, 5, FALSE) -> #N/A | G21: =VLOOKUP($A21, Table_S1!$B$10:$K$5118, 6, FALSE) -> #N/A | H21: =VLOOKUP($A21, Table_S1!$B$10:$K$5118, 7, FALSE) -> #N/A | I21: =VLOOKUP($A21, Table_S1!$B$10:$K$5118, 8, FALSE) -> #N/A | J21: =VLOOKUP($A21, Table_S1!$B$10:$K$5118, 9, FALSE) -> #N/A | K21: =VLOOKUP($A21, Table_S1!$B$10:$K$5118, 10, FALSE) -> #N/A | M21: ='Raw Data'!C32 -> IRMOF-6 | N21: ='Raw Data'!I32 -> 19.5 | O21: ='Raw Data'!N32 -> 2516 | P21: ='Raw Data'!O32 -> / | Q21: 10, 15A | R21: ='Raw Data'!Q32 -> / | S21: ='Raw Data'!L32 -> 298 | T21: ='Raw Data'!M32 -> 32 bar | V21: ='Raw Data'!U32 -> ^^^ | Z21: PD: A.R. Millward, O.M. Yaghi Metal-organic frameworks with exceptionally high capacity for storage of carbon dioxide at room temperature J Am Chem Soc, 127 (51) (2005), pp. 17998-17999
A22: ='Raw Data'!E33 -> EDUSIF | B22: =M22 -> IRMOF-1 | C22: =VLOOKUP($A22, Table_S1!$B$10:$K$5118, 2, FALSE) -> Zn | D22: =VLOOKUP($A22, Table_S1!$B$10:$K$5118, 3, FALSE) -> 0.593338 | E22: =VLOOKUP($A22, Table_S1!$B$10:$K$5118, 4, FALSE) -> 7.91583 | F22: =VLOOKUP($A22, Table_S1!$B$10:$K$5118, 5, FALSE) -> 15.06639 | G22: =VLOOKUP($A22, Table_S1!$B$10:$K$5118, 6, FALSE) -> 2156.27 | H22: =VLOOKUP($A22, Table_S1!$B$10:$K$5118, 7, FALSE) -> 3634.13 | I22: =VLOOKUP($A22, Table_S1!$B$10:$K$5118, 8, FALSE) -> 0.829192 | J22: =VLOOKUP($A22, Table_S1!$B$10:$K$5118, 9, FALSE) -> 1.36205 | K22: =VLOOKUP($A22, Table_S1!$B$10:$K$5118, 10, FALSE) -> 0 | M22: ='Raw Data'!C33 -> IRMOF-1 | N22: ='Raw Data'!I33 -> 21.7 | O22: ='Raw Data'!N33 -> 2833 | P22: 1.319 | Q22: 12, 15A | R22: ='Raw Data'!Q33 -> / | S22: ='Raw Data'!L33 -> 298 | T22: ='Raw Data'!M33 -> 32 bar | V22: ='Raw Data'!U33 -> ^^^ | Y22: Furukawa H., Miller M. A., Yaghi O. M., Independent verification of the saturation hydrogen uptake in MOF-177 and establishment of a benchmark for hydrogen adsorption in metal–organic frameworks. J. Mater. Chem. 17, 3197 (2007). | Z22: A.R. Millward, O.M. Yaghi Metal-organic frameworks with exceptionally high capacity for storage of carbon dioxide at room temperature J Am Chem Soc, 127 (51) (2005), pp. 17998-17999 PV: A.O. Yazaydin, R.Q. Snurr, T.H. Park, K. Koh, J. Liu, M.D. LeVan, A.I. Benin, P. Jakubczak, M. Lanuza, D.B. Galloway, J.J. Low Screening of metal-organic frameworks for carbon dioxide capture from flue gas using a combined experimental and modeling approach J Am Chem Soc, 131 (51) (2009), pp. 18198-18199
A23: ='Raw Data'!E35 -> VUJBIM | B23: =M23 -> PCN-61 | C23: =VLOOKUP($A23, Table_S1!$B$10:$K$5118, 2, FALSE) -> Cu | D23: =VLOOKUP($A23, Table_S1!$B$10:$K$5118, 3, FALSE) -> 0.560742 | E23: =VLOOKUP($A23, Table_S1!$B$10:$K$5118, 4, FALSE) -> 6.62187 | F23: =VLOOKUP($A23, Table_S1!$B$10:$K$5118, 5, FALSE) -> 18.70668 | G23: =VLOOKUP($A23, Table_S1!$B$10:$K$5118, 6, FALSE) -> 2086.69 | H23: =VLOOKUP($A23, Table_S1!$B$10:$K$5118, 7, FALSE) -> 3721.31 | I23: =VLOOKUP($A23, Table_S1!$B$10:$K$5118, 8, FALSE) -> 0.846988 | J23: =VLOOKUP($A23, Table_S1!$B$10:$K$5118, 9, FALSE) -> 1.41413 | K23: =VLOOKUP($A23, Table_S1!$B$10:$K$5118, 10, FALSE) -> 0 | M23: ='Raw Data'!C35 -> PCN-61 | N23: ='Raw Data'!I35 -> 23.5 | O23: ='Raw Data'!N35 -> 3000 | P23: ='Raw Data'!O35 -> 1.36 | Q23: ='Raw Data'!P35 -> / | R23: ='Raw Data'!Q35 -> / | S23: ='Raw Data'!L35 -> 298 | T23: ='Raw Data'!M35 -> 35 bar | V23: ='Raw Data'!U35 -> D. Yuan, D. Zhao, D. Sun, H.C. Zhou An isoreticular series of metal–organic frameworks with dendritic hexacarboxylate ligands and exceptionally high gas-uptake capacity Angew Chem, 122 (31) (2010), pp. 5485-548
A24: ='Raw Data'!E36 -> VUJBOS | B24: =M24 -> PCN-66 | C24: =VLOOKUP($A24, Table_S1!$B$10:$K$5118, 2, FALSE) -> #N/A | D24: =VLOOKUP($A24, Table_S1!$B$10:$K$5118, 3, FALSE) -> #N/A | E24: =VLOOKUP($A24, Table_S1!$B$10:$K$5118, 4, FALSE) -> #N/A | F24: =VLOOKUP($A24, Table_S1!$B$10:$K$5118, 5, FALSE) -> #N/A | G24: =VLOOKUP($A24, Table_S1!$B$10:$K$5118, 6, FALSE) -> #N/A | H24: =VLOOKUP($A24, Table_S1!$B$10:$K$5118, 7, FALSE) -> #N/A | I24: =VLOOKUP($A24, Table_S1!$B$10:$K$5118, 8, FALSE) -> #N/A | J24: =VLOOKUP($A24, Table_S1!$B$10:$K$5118, 9, FALSE) -> #N/A | K24: =VLOOKUP($A24, Table_S1!$B$10:$K$5118, 10, FALSE) -> #N/A | M24: ='Raw Data'!C36 -> PCN-66 | N24: ='Raw Data'!I36 -> 26.3 | O24: ='Raw Data'!N36 -> 4000 | P24: ='Raw Data'!O36 -> 1.63 | Q24: ='Raw Data'!P36 -> / | R24: ='Raw Data'!Q36 -> / | S24: ='Raw Data'!L36 -> 298 | T24: ='Raw Data'!M36 -> 35 bar | V24: ='Raw Data'!U36 -> ^^^
A25: ='Raw Data'!E37 -> HABRAF | B25: =M25 -> PCN-68 | C25: =VLOOKUP($A25, Table_S1!$B$10:$K$5118, 2, FALSE) -> Cu | D25: =VLOOKUP($A25, Table_S1!$B$10:$K$5118, 3, FALSE) -> 0.38234 | E25: =VLOOKUP($A25, Table_S1!$B$10:$K$5118, 4, FALSE) -> 9.03547 | F25: =VLOOKUP($A25, Table_S1!$B$10:$K$5118, 5, FALSE) -> 24.30025 | G25: =VLOOKUP($A25, Table_S1!$B$10:$K$5118, 6, FALSE) -> 1854.22 | H25: =VLOOKUP($A25, Table_S1!$B$10:$K$5118, 7, FALSE) -> 4849.67 | I25: =VLOOKUP($A25, Table_S1!$B$10:$K$5118, 8, FALSE) -> 0.889946 | J25: =VLOOKUP($A25, Table_S1!$B$10:$K$5118, 9, FALSE) -> 2.21088 | K25: =VLOOKUP($A25, Table_S1!$B$10:$K$5118, 10, FALSE) -> removed duplicates + geom. Minimization | M25: ='Raw Data'!C37 -> PCN-68 | N25: ='Raw Data'!I37 -> 30.4 | O25: ='Raw Data'!N37 -> 5109 | P25: ='Raw Data'!O37 -> 2.13 | Q25: ='Raw Data'!P37 -> / | R25: ='Raw Data'!Q37 -> / | S25: ='Raw Data'!L37 -> 298 | T25: ='Raw Data'!M37 -> 35 bar | V25: ='Raw Data'!U37 -> ^^^
A26: ='Raw Data'!E40 -> DOTSOV42 | B26: =M26 -> HKUST-1 | C26: =VLOOKUP($A26, Table_S1!$B$10:$K$5118, 2, FALSE) -> Cu | D26: =VLOOKUP($A26, Table_S1!$B$10:$K$5118, 3, FALSE) -> 0.88463 | E26: =VLOOKUP($A26, Table_S1!$B$10:$K$5118, 4, FALSE) -> 6.68237 | F26: =VLOOKUP($A26, Table_S1!$B$10:$K$5118, 5, FALSE) -> 13.28197 | G26: =VLOOKUP($A26, Table_S1!$B$10:$K$5118, 6, FALSE) -> 1832.89 | H26: =VLOOKUP($A26, Table_S1!$B$10:$K$5118, 7, FALSE) -> 2070.82 | I26: =VLOOKUP($A26, Table_S1!$B$10:$K$5118, 8, FALSE) -> 0.751817 | J26: =VLOOKUP($A26, Table_S1!$B$10:$K$5118, 9, FALSE) -> 0.812183 | K26: =VLOOKUP($A26, Table_S1!$B$10:$K$5118, 10, FALSE) -> 0 | M26: ='Raw Data'!C40 -> HKUST-1 | N26: ='Raw Data'!I40 -> 5.1 | O26: ='Raw Data'!N40 -> 2134 | P26: 0.801 | Q26: ='Raw Data'!P40 -> 5.05/10.45/12.4 | R26: ='Raw Data'!Q40 -> / | S26: ='Raw Data'!L40 -> 295 | T26: ='Raw Data'!M40 -> 1 | V26: ='Raw Data'!U40 -> A.O. Yazaydin, R.Q. Snurr, T.H. Park, K. Koh, J. Liu, M.D. LeVan, A.I. Benin, P. Jakubczak, M. Lanuza, D.B. Galloway, J.J. Low Screening of metal-organic frameworks for carbon dioxide capture from flue gas using a combined experimental and modeling approach J Am Chem Soc, 131 (51) (2009), pp. 18198-18199 | Y26: Furukawa H., Miller M. A., Yaghi O. M., Independent verification of the saturation hydrogen uptake in MOF-177 and establishment of a benchmark for hydrogen adsorption in metal–organic frameworks. J. Mater. Chem. 17, 3197 (2007).
A27: ='Raw Data'!E41 -> OKABEI | B27: =M27 -> UMCM-150 | C27: =VLOOKUP($A27, Table_S1!$B$10:$K$5118, 2, FALSE) -> Cu | D27: =VLOOKUP($A27, Table_S1!$B$10:$K$5118, 3, FALSE) -> 0.653017 | E27: =VLOOKUP($A27, Table_S1!$B$10:$K$5118, 4, FALSE) -> 9.42284 | F27: =VLOOKUP($A27, Table_S1!$B$10:$K$5118, 5, FALSE) -> 13.86987 | G27: =VLOOKUP($A27, Table_S1!$B$10:$K$5118, 6, FALSE) -> 2030.48 | H27: =VLOOKUP($A27, Table_S1!$B$10:$K$5118, 7, FALSE) -> 3109.38 | I27: =VLOOKUP($A27, Table_S1!$B$10:$K$5118, 8, FALSE) -> 0.825521 | J27: =VLOOKUP($A27, Table_S1!$B$10:$K$5118, 9, FALSE) -> 1.18812 | K27: =VLOOKUP($A27, Table_S1!$B$10:$K$5118, 10, FALSE) -> 0 | M27: ='Raw Data'!C41 -> UMCM-150 | N27: ='Raw Data'!I41 -> 2.6 | O27: ='Raw Data'!N41 -> 3236 | P27: 1.186 | Q27: ='Raw Data'!P41 -> 9.25/10.55/13.25 | R27: ='Raw Data'!Q41 -> / | S27: ='Raw Data'!L41 -> 298 | T27: ='Raw Data'!M41 -> 1 | V27: ='Raw Data'!U41 -> ^^^ | Y27: A.O. Yazaydin, R.Q. Snurr, T.H. Park, K. Koh, J. Liu, M.D. LeVan, A.I. Benin, P. Jakubczak, M. Lanuza, D.B. Galloway, J.J. Low Screening of metal-organic frameworks for carbon dioxide capture from flue gas using a combined experimental and modeling approach J Am Chem Soc, 131 (51) (2009), pp. 18198-18199
A28: ='Raw Data'!E42 -> OKABAE | B28: =M28 -> UMCM-150(N)2 | C28: =VLOOKUP($A28, Table_S1!$B$10:$K$5118, 2, FALSE) -> Cu | D28: =VLOOKUP($A28, Table_S1!$B$10:$K$5118, 3, FALSE) -> 0.650845 | E28: =VLOOKUP($A28, Table_S1!$B$10:$K$5118, 4, FALSE) -> 9.53484 | F28: =VLOOKUP($A28, Table_S1!$B$10:$K$5118, 5, FALSE) -> 14.07417 | G28: =VLOOKUP($A28, Table_S1!$B$10:$K$5118, 6, FALSE) -> 2034.36 | H28: =VLOOKUP($A28, Table_S1!$B$10:$K$5118, 7, FALSE) -> 3125.73 | I28: =VLOOKUP($A28, Table_S1!$B$10:$K$5118, 8, FALSE) -> 0.822327 | J28: =VLOOKUP($A28, Table_S1!$B$10:$K$5118, 9, FALSE) -> 1.19593 | K28: =VLOOKUP($A28, Table_S1!$B$10:$K$5118, 10, FALSE) -> 0 | M28: ='Raw Data'!C42 -> UMCM-150(N)2 | N28: ='Raw Data'!I42 -> 2.7 | O28: ='Raw Data'!N42 -> 3110 | P28: 1.168 | Q28: ='Raw Data'!P42 -> 9.45/11.55/13.35 | R28: ='Raw Data'!Q42 -> / | S28: ='Raw Data'!L42 -> 298 | T28: ='Raw Data'!M42 -> 1 | V28: ='Raw Data'!U42 -> ^^^
A29: ='Raw Data'!E43 -> HEJPIZ | B29: =M29 -> MIL-47 | C29: =VLOOKUP($A29, Table_S1!$B$10:$K$5118, 2, FALSE) -> #N/A | D29: =VLOOKUP($A29, Table_S1!$B$10:$K$5118, 3, FALSE) -> #N/A | E29: =VLOOKUP($A29, Table_S1!$B$10:$K$5118, 4, FALSE) -> #N/A | F29: =VLOOKUP($A29, Table_S1!$B$10:$K$5118, 5, FALSE) -> #N/A | G29: =VLOOKUP($A29, Table_S1!$B$10:$K$5118, 6, FALSE) -> #N/A | H29: =VLOOKUP($A29, Table_S1!$B$10:$K$5118, 7, FALSE) -> #N/A | I29: =VLOOKUP($A29, Table_S1!$B$10:$K$5118, 8, FALSE) -> #N/A | J29: =VLOOKUP($A29, Table_S1!$B$10:$K$5118, 9, FALSE) -> #N/A | K29: =VLOOKUP($A29, Table_S1!$B$10:$K$5118, 10, FALSE) -> #N/A | M29: ='Raw Data'!C43 -> MIL-47 | N29: ='Raw Data'!I43 -> 2 | O29: ='Raw Data'!N43 -> 1511 | P29: 0.604 | Q29: ='Raw Data'!P43 -> 7.35 | R29: ='Raw Data'!Q43 -> / | S29: ='Raw Data'!L43 -> 298 | T29: ='Raw Data'!M43 -> 1 | V29: ='Raw Data'!U43 -> ^^^
A30: ='Raw Data'!E44 -> BABRII | B30: =M30 -> MOF-177 | C30: =VLOOKUP($A30, Table_S1!$B$10:$K$5118, 2, FALSE) -> #N/A | D30: =VLOOKUP($A30, Table_S1!$B$10:$K$5118, 3, FALSE) -> #N/A | E30: =VLOOKUP($A30, Table_S1!$B$10:$K$5118, 4, FALSE) -> #N/A | F30: =VLOOKUP($A30, Table_S1!$B$10:$K$5118, 5, FALSE) -> #N/A | G30: =VLOOKUP($A30, Table_S1!$B$10:$K$5118, 6, FALSE) -> #N/A | H30: =VLOOKUP($A30, Table_S1!$B$10:$K$5118, 7, FALSE) -> #N/A | I30: =VLOOKUP($A30, Table_S1!$B$10:$K$5118, 8, FALSE) -> #N/A | J30: =VLOOKUP($A30, Table_S1!$B$10:$K$5118, 9, FALSE) -> #N/A | K30: =VLOOKUP($A30, Table_S1!$B$10:$K$5118, 10, FALSE) -> #N/A | M30: ='Raw Data'!C44 -> MOF-177 | N30: ='Raw Data'!I44 -> 1.6 | O30: ='Raw Data'!N44 -> 4833 | P30: 1.89 | Q30: ='Raw Data'!P44 -> 10.45 | R30: 0.43 | S30: ='Raw Data'!L44 -> 298 | T30: ='Raw Data'!M44 -> 1 | V30: ='Raw Data'!U44 -> ^^^ | Y30: Furukawa H., Miller M. A., Yaghi O. M., Independent verification of the saturation hydrogen uptake in MOF-177 and establishment of a benchmark for hydrogen adsorption in metal–organic frameworks. J. Mater. Chem. 17, 3197 (2007). | AA30: Furukawa H., Miller M. A., Yaghi O. M., Independent verification of the saturation hydrogen uptake in MOF-177 and establishment of a benchmark for hydrogen adsorption in metal–organic frameworks. J. Mater. Chem. 17, 3197 (2007).
A31: ='Raw Data'!E45 -> EDUSUR | B31: =M31 -> IRMOF-3 | C31: =VLOOKUP($A31, Table_S1!$B$10:$K$5118, 2, FALSE) -> #N/A | D31: =VLOOKUP($A31, Table_S1!$B$10:$K$5118, 3, FALSE) -> #N/A | E31: =VLOOKUP($A31, Table_S1!$B$10:$K$5118, 4, FALSE) -> #N/A | F31: =VLOOKUP($A31, Table_S1!$B$10:$K$5118, 5, FALSE) -> #N/A | G31: =VLOOKUP($A31, Table_S1!$B$10:$K$5118, 6, FALSE) -> #N/A | H31: =VLOOKUP($A31, Table_S1!$B$10:$K$5118, 7, FALSE) -> #N/A | I31: =VLOOKUP($A31, Table_S1!$B$10:$K$5118, 8, FALSE) -> #N/A | J31: =VLOOKUP($A31, Table_S1!$B$10:$K$5118, 9, FALSE) -> #N/A | K31: =VLOOKUP($A31, Table_S1!$B$10:$K$5118, 10, FALSE) -> #N/A | M31: ='Raw Data'!C45 -> IRMOF-3 | N31: ='Raw Data'!I45 -> 1.1 | O31: ='Raw Data'!N45 -> 3365 | P31: 1.204 | Q31: ='Raw Data'!P45 -> 8.65/14.25 | R31: ='Raw Data'!Q45 -> / | S31: ='Raw Data'!L45 -> 298 | T31: ='Raw Data'!M45 -> 1 | V31: ='Raw Data'!U45 -> ^^^
A32: ='Raw Data'!E46 -> KISXIU | B32: =M32 -> UMCM-1 | C32: =VLOOKUP($A32, Table_S1!$B$10:$K$5118, 2, FALSE) -> #N/A | D32: =VLOOKUP($A32, Table_S1!$B$10:$K$5118, 3, FALSE) -> #N/A | E32: =VLOOKUP($A32, Table_S1!$B$10:$K$5118, 4, FALSE) -> #N/A | F32: =VLOOKUP($A32, Table_S1!$B$10:$K$5118, 5, FALSE) -> #N/A | G32: =VLOOKUP($A32, Table_S1!$B$10:$K$5118, 6, FALSE) -> #N/A | H32: =VLOOKUP($A32, Table_S1!$B$10:$K$5118, 7, FALSE) -> #N/A | I32: =VLOOKUP($A32, Table_S1!$B$10:$K$5118, 8, FALSE) -> #N/A | J32: =VLOOKUP($A32, Table_S1!$B$10:$K$5118, 9, FALSE) -> #N/A | K32: =VLOOKUP($A32, Table_S1!$B$10:$K$5118, 10, FALSE) -> #N/A | M32: ='Raw Data'!C46 -> UMCM-1 | N32: ='Raw Data'!I46 -> 0.9 | O32: ='Raw Data'!N46 -> 4972 | P32: 2.146 | Q32: ='Raw Data'!P46 -> 10.45/14.05/23.75 | R32: ='Raw Data'!Q46 -> / | S32: ='Raw Data'!L46 -> 298 | T32: ='Raw Data'!M46 -> 1 | V32: ='Raw Data'!U46 -> ^^^ | Y32: Furukawa H., Miller M. A., Yaghi O. M., Independent verification of the saturation hydrogen uptake in MOF-177 and establishment of a benchmark for hydrogen adsorption in metal–organic frameworks. J. Mater. Chem. 17, 3197 (2007).
A33: ='Raw Data'!E47 -> EDUSIF | B33: =M33 -> IRMOF-1 | C33: =VLOOKUP($A33, Table_S1!$B$10:$K$5118, 2, FALSE) -> Zn | D33: =VLOOKUP($A33, Table_S1!$B$10:$K$5118, 3, FALSE) -> 0.593338 | E33: =VLOOKUP($A33, Table_S1!$B$10:$K$5118, 4, FALSE) -> 7.91583 | F33: =VLOOKUP($A33, Table_S1!$B$10:$K$5118, 5, FALSE) -> 15.06639 | G33: =VLOOKUP($A33, Table_S1!$B$10:$K$5118, 6, FALSE) -> 2156.27 | H33: =VLOOKUP($A33, Table_S1!$B$10:$K$5118, 7, FALSE) -> 3634.13 | I33: =VLOOKUP($A33, Table_S1!$B$10:$K$5118, 8, FALSE) -> 0.829192 | J33: =VLOOKUP($A33, Table_S1!$B$10:$K$5118, 9, FALSE) -> 1.36205 | K33: =VLOOKUP($A33, Table_S1!$B$10:$K$5118, 10, FALSE) -> 0 | M33: ='Raw Data'!C47 -> IRMOF-1 | N33: ='Raw Data'!I47 -> 0.8 | O33: ='Raw Data'!N47 -> 3562 | P33: 1.319 | Q33: ='Raw Data'!P47 -> 11.25/14.45 | R33: ='Raw Data'!Q47 -> / | S33: ='Raw Data'!L47 -> 298 | T33: ='Raw Data'!M47 -> 1 | V33: ='Raw Data'!U47 -> ^^^ | Y33: Furukawa H., Miller M. A., Yaghi O. M., Independent verification of the saturation hydrogen uptake in MOF-177 and establishment of a benchmark for hydrogen adsorption in metal–organic frameworks. J. Mater. Chem. 17, 3197 (2007).
A34: ='Raw Data'!E50 -> ORIVOC | B34: =M34 -> Zn-MOF-74 | C34: =VLOOKUP($A34, Table_S1!$B$10:$K$5118, 2, FALSE) -> #N/A | D34: =VLOOKUP($A34, Table_S1!$B$10:$K$5118, 3, FALSE) -> #N/A | E34: =VLOOKUP($A34, Table_S1!$B$10:$K$5118, 4, FALSE) -> #N/A | F34: =VLOOKUP($A34, Table_S1!$B$10:$K$5118, 5, FALSE) -> #N/A | G34: =VLOOKUP($A34, Table_S1!$B$10:$K$5118, 6, FALSE) -> #N/A | H34: =VLOOKUP($A34, Table_S1!$B$10:$K$5118, 7, FALSE) -> #N/A | I34: =VLOOKUP($A34, Table_S1!$B$10:$K$5118, 8, FALSE) -> #N/A | J34: =VLOOKUP($A34, Table_S1!$B$10:$K$5118, 9, FALSE) -> #N/A | K34: =VLOOKUP($A34, Table_S1!$B$10:$K$5118, 10, FALSE) -> #N/A | M34: ='Raw Data'!C50 -> Zn-MOF-74 | N34: ='Raw Data'!I50 -> 5.5 | O34: ='Raw Data'!N50 -> 816 | P34: ='Raw Data'!O50 -> ND | Q34: ='Raw Data'!P50 -> / | R34: ='Raw Data'!Q50 -> / | S34: ='Raw Data'!L50 -> 298 | T34: ='Raw Data'!M50 -> 1.013 | V34: ='Raw Data'!U50 -> A.O. Yazaydin, R.Q. Snurr, T.H. Park, K. Koh, J. Liu, M.D. LeVan, A.I. Benin, P. Jakubczak, M. Lanuza, D.B. Galloway, J.J. Low Screening of metal-organic frameworks for carbon dioxide capture from flue gas using a combined experimental and modeling approach J Am Chem Soc, 131 (51) (2009), pp. 18198-18199
A35: ='Raw Data'!E51 -> ORIVUI | B35: =M35 -> Ni-MOF-74 | C35: =VLOOKUP($A35, Table_S1!$B$10:$K$5118, 2, FALSE) -> #N/A | D35: =VLOOKUP($A35, Table_S1!$B$10:$K$5118, 3, FALSE) -> #N/A | E35: =VLOOKUP($A35, Table_S1!$B$10:$K$5118, 4, FALSE) -> #N/A | F35: =VLOOKUP($A35, Table_S1!$B$10:$K$5118, 5, FALSE) -> #N/A | G35: =VLOOKUP($A35, Table_S1!$B$10:$K$5118, 6, FALSE) -> #N/A | H35: =VLOOKUP($A35, Table_S1!$B$10:$K$5118, 7, FALSE) -> #N/A | I35: =VLOOKUP($A35, Table_S1!$B$10:$K$5118, 8, FALSE) -> #N/A | J35: =VLOOKUP($A35, Table_S1!$B$10:$K$5118, 9, FALSE) -> #N/A | K35: =VLOOKUP($A35, Table_S1!$B$10:$K$5118, 10, FALSE) -> #N/A | M35: ='Raw Data'!C51 -> Ni-MOF-74 | N35: ='Raw Data'!I51 -> 5.8 | O35: ='Raw Data'!N51 -> 1070 | P35: ='Raw Data'!O51 -> / | Q35: ='Raw Data'!P51 -> / | R35: ='Raw Data'!Q51 -> / | S35: ='Raw Data'!L51 -> 298 | T35: ='Raw Data'!M51 -> 1.013 | V35: ='Raw Data'!U51 -> ^^^
A36: ='Raw Data'!E52 -> ORIWAP | B36: =M36 -> Co-MOF-74 | C36: =VLOOKUP($A36, Table_S1!$B$10:$K$5118, 2, FALSE) -> #N/A | D36: =VLOOKUP($A36, Table_S1!$B$10:$K$5118, 3, FALSE) -> #N/A | E36: =VLOOKUP($A36, Table_S1!$B$10:$K$5118, 4, FALSE) -> #N/A | F36: =VLOOKUP($A36, Table_S1!$B$10:$K$5118, 5, FALSE) -> #N/A | G36: =VLOOKUP($A36, Table_S1!$B$10:$K$5118, 6, FALSE) -> #N/A | H36: =VLOOKUP($A36, Table_S1!$B$10:$K$5118, 7, FALSE) -> #N/A | I36: =VLOOKUP($A36, Table_S1!$B$10:$K$5118, 8, FALSE) -> #N/A | J36: =VLOOKUP($A36, Table_S1!$B$10:$K$5118, 9, FALSE) -> #N/A | K36: =VLOOKUP($A36, Table_S1!$B$10:$K$5118, 10, FALSE) -> #N/A | M36: ='Raw Data'!C52 -> Co-MOF-74 | N36: ='Raw Data'!I52 -> 7 | O36: ='Raw Data'!N52 -> 1080 | P36: ='Raw Data'!O52 -> / | Q36: ='Raw Data'!P52 -> / | R36: ='Raw Data'!Q52 -> / | S36: ='Raw Data'!L52 -> 298 | T36: ='Raw Data'!M52 -> 1.013 | V36: ='Raw Data'!U52 -> ^^^
A37: ='Raw Data'!E53 -> / | B37: =M37 -> Mg-MOF-74 | C37: =VLOOKUP($A37, Table_S1!$B$10:$K$5118, 2, FALSE) -> #N/A | D37: =VLOOKUP($A37, Table_S1!$B$10:$K$5118, 3, FALSE) -> #N/A | E37: =VLOOKUP($A37, Table_S1!$B$10:$K$5118, 4, FALSE) -> #N/A | F37: =VLOOKUP($A37, Table_S1!$B$10:$K$5118, 5, FALSE) -> #N/A | G37: =VLOOKUP($A37, Table_S1!$B$10:$K$5118, 6, FALSE) -> #N/A | H37: =VLOOKUP($A37, Table_S1!$B$10:$K$5118, 7, FALSE) -> #N/A | I37: =VLOOKUP($A37, Table_S1!$B$10:$K$5118, 8, FALSE) -> #N/A | J37: =VLOOKUP($A37, Table_S1!$B$10:$K$5118, 9, FALSE) -> #N/A | K37: =VLOOKUP($A37, Table_S1!$B$10:$K$5118, 10, FALSE) -> #N/A | M37: ='Raw Data'!C53 -> Mg-MOF-74 | N37: ='Raw Data'!I53 -> 8.5 | O37: ='Raw Data'!N53 -> 1495 | P37: ='Raw Data'!O53 -> / | Q37: ='Raw Data'!P53 -> / | R37: ='Raw Data'!Q53 -> / | S37: ='Raw Data'!L53 -> 298 | T37: ='Raw Data'!M53 -> 1.013 | V37: ='Raw Data'!U53 -> ^^^
